<?xml version="1.0"?>
<robot xmlns:xacro="http://ros.org/wiki/xacro" name="zenorak">

    <link name="base_link">
        <inertial>
            <origin xyz="0.00169935610472678 -0.0264088300158522 -0.00887384287152697" rpy="0 0 0" />
            <mass value="53.468367880832" />
            <inertia ixx="2.31995848291568" ixy="-0.0135330136565553" ixz="0.00962962421966709" iyy="5.75370953859927" iyz="-0.015886629814071" izz="7.30712487101093" />
        </inertial>
        <visual>
            <origin xyz="0 0 0" rpy="0 0 0" />
            <geometry>
                <mesh filename="file://$(find zenorak_ros2_control)/meshes/visual/base_link.STL" />
            </geometry>
            <material name="">
                <color rgba="0.792156862745098 0.819607843137255 0.933333333333333 1" />
            </material>
        </visual>
        <collision>
            <origin xyz="0 0 0" rpy="0 0 0" />
            <geometry>
                <mesh filename="file://$(find zenorak_ros2_control)/meshes/collision/base_link.STL" />
            </geometry>
        </collision>
    </link>
    <link name="front_left_wheel">
        <inertial>
            <origin xyz="1.58206781009085E-15 8.04911692853238E-16 0.0547827108814377" rpy="0 0 0" />
            <mass value="7.16104527274178" />
            <inertia ixx="0.0473444268968467" ixy="-3.03576608295941E-18" ixz="1.55929200281309E-18" iyy="0.0473444268968467" iyz="2.99484885934959E-19" izz="0.0801617478666343" />
        </inertial>
        <visual>
            <origin xyz="0 0 0" rpy="0 0 0" />
            <geometry>
                <mesh filename="file://$(find zenorak_ros2_control)/meshes/visual/front_left_wheel.STL" />
            </geometry>
            <material name="">
                <color rgba="0.792156862745098 0.819607843137255 0.933333333333333 1" />
            </material>
        </visual>
        <collision>
            <origin xyz="0 0 0" rpy="0 0 0" />
            <geometry>
                <mesh filename="file://$(find zenorak_ros2_control)/meshes/collision/front_left_wheel.STL" />
            </geometry>
        </collision>
    </link>
    <joint name="front_left_wheel_joint" type="continuous">
        <origin xyz="0.23992 -0.26239 -0.15849" rpy="1.5708 -0.1528 0" />
        <parent link="base_link" />
        <child link="front_left_wheel" />
        <axis xyz="0 0 1" />
    </joint>
    <link name="rear_left_wheel">
        <inertial>
            <origin xyz="6.10622663543836E-15 3.02535774210355E-15 0.0547827108814376" rpy="0 0 0" />
            <mass value="7.16104527274178" />
            <inertia ixx="0.0473444268968467" ixy="-5.20417042793042E-18" ixz="-7.65975378716319E-19" iyy="0.0473444268968467" iyz="1.65118432328216E-19" izz="0.0801617478666342" />
        </inertial>
        <visual>
            <origin xyz="0 0 0" rpy="0 0 0" />
            <geometry>
                <mesh filename="file://$(find zenorak_ros2_control)/meshes/visual/rear_left_wheel.STL" />
            </geometry>
            <material name="">
                <color rgba="0.792156862745098 0.819607843137255 0.933333333333333 1" />
            </material>
        </visual>
        <collision>
            <origin xyz="0 0 0" rpy="0 0 0" />
            <geometry>
                <mesh filename="file://$(find zenorak_ros2_control)/meshes/collision/rear_left_wheel.STL" />
            </geometry>
        </collision>
    </link>
    <joint name="rear_left_wheel_joint" type="continuous">
        <origin xyz="-0.3492 -0.26239 -0.15849" rpy="1.5708 -0.82404 0" />
        <parent link="base_link" />
        <child link="rear_left_wheel" />
        <axis xyz="0 0 1" />
    </joint>
    <link name="front_right_wheel">
        <inertial>
            <origin xyz="8.21565038222616E-15 3.73312492030209E-15 0.0547827108814377" rpy="0 0 0" />
            <mass value="7.16104527274178" />
            <inertia ixx="0.0473444268968467" ixy="-1.38777878078145E-17" ixz="-5.7829154300703E-17" iyy="0.0473444268968467" iyz="5.0895068506072E-17" izz="0.0801617478666342" />
        </inertial>
        <visual>
            <origin xyz="0 0 0" rpy="0 0 0" />
            <geometry>
                <mesh filename="file://$(find zenorak_ros2_control)/meshes/visual/front_right_wheel.STL" />
            </geometry>
            <material name="">
                <color rgba="0.792156862745098 0.819607843137255 0.933333333333333 1" />
            </material>
        </visual>
        <collision>
            <origin xyz="0 0 0" rpy="0 0 0" />
            <geometry>
                <mesh filename="file://$(find zenorak_ros2_control)/meshes/collision/front_right_wheel.STL" />
            </geometry>
        </collision>
    </link>
    <joint name="front_right_wheel_joint" type="continuous">
        <origin xyz="0.23992 0.20761 -0.15849" rpy="-1.5708 0.70348 0" />
        <parent link="base_link" />
        <child link="front_right_wheel" />
        <axis xyz="0 0 1" />
    </joint>
    <link name="rear_right_wheel">
        <inertial>
            <origin xyz="5.21804821573824E-15 1.0547118733939E-15 0.0547827108814375" rpy="0 0 0" />
            <mass value="7.16104527274178" />
            <inertia ixx="0.0473444268968467" ixy="-3.46944695195361E-18" ixz="1.83167009339647E-17" iyy="0.0473444268968467" iyz="1.33511956035853E-17" izz="0.0801617478666343" />
        </inertial>
        <visual>
            <origin xyz="0 0 0" rpy="0 0 0" />
            <geometry>
                <mesh filename="file://$(find zenorak_ros2_control)/meshes/visual/rear_right_wheel.STL" />
            </geometry>
            <material name="">
                <color rgba="0.792156862745098 0.819607843137255 0.933333333333333 1" />
            </material>
        </visual>
        <collision>
            <origin xyz="0 0 0" rpy="0 0 0" />
            <geometry>
                <mesh filename="file://$(find zenorak_ros2_control)/meshes/collision/rear_right_wheel.STL" />
            </geometry>
        </collision>
    </link>
    <joint name="rear_right_wheel_joint" type="continuous">
        <origin xyz="-0.3492 0.20761 -0.15849" rpy="-1.5708 -1.1782 0" />
        <parent link="base_link" />
        <child link="rear_right_wheel" />
        <axis xyz="0 0 1" />
    </joint>
    <ros2_control name="zenorak_control" type="system">
        <hardware>
            <plugin>diffdrive_arduino/DiffDriveArduinoHardware</plugin>
            <param name="left_wheel_name">front_left_wheel</param>
            <param name="right_wheel_name">front_right_wheel</param>
            <param name="loop_rate">30</param>
            <param name="device">/dev/ttyACM0</param>
            <param name="baud_rate">57600</param>
            <param name="timeout_ms">1000</param>
            <param name="enc_counts_per_rev">3436</param>
        </hardware>
        <joint name="front_left_wheel">
            <state_interface name="position"/>
            <state_interface name="velocity"/>
            <command_interface name="velocity">
                <param name="min">-10</param>
                <param name="max">10</param>
            </command_interface>
        </joint>
        <joint name="front_right_wheel">
            <state_interface name="position"/>
            <state_interface name="velocity"/>
            <command_interface name="velocity">
                <param name="min">-10</param>
                <param name="max">10</param>
            </command_interface>
        </joint>
    </ros2_control>
</robot>